<?xml version="1.0" ?>
<!-- =================================================================================== -->
<!-- |    This document was autogenerated by xacro from use_robot.xacro                | -->
<!-- |    EDITING THIS FILE BY HAND IS NOT RECOMMENDED                                 | -->
<!-- =================================================================================== -->
<robot name="my_robot" xmlns:xacro="http://www.ros.org/wiki/xacro">
  <material name="yellow">
    <color rgba="1 0.4 0 1"/>
  </material>
  <material name="black">
    <color rgba="0 0 0 0.95"/>
  </material>
  <material name="blue">
    <color rgba="0 0 1 1"/>
  </material>
  <material name="gray">
    <color rgba="0.75 0.75 0.75 0.95"/>
  </material>
  <link name="base_footprint">
    <visual>
      <origin rpy="0 0 0" xyz="0 0 0"/>
      <geometry>
        <box size="0.001 0.001 0.001"/>
      </geometry>
    </visual>
  </link>
  <joint name="base_footprint" type="fixed">
    <origin rpy="0 0 0" xyz="0 0 0.13"/>
    <parent link="base_footprint"/>
    <child link="base_link"/>
  </joint>
  <link name="base_link">
    <visual>
      <origin rpy="0 0 0" xyz="0 0 0"/>
      <geometry>
        <cylinder length="0.16" radius="0.2"/>
      </geometry>
      <material name="blue"/>
    </visual>
  </link>
  <joint name="left_wheel_joint" type="continuous">
    <origin rpy="0 0 0" xyz="0 -0.19 -0.07"/>
    <parent link="base_link"/>
    <child link="left_wheel_link"/>
    <axis xyz="0 1 0"/>
  </joint>
  <link name="left_wheel_link">
    <visual>
      <origin rpy="1.5707963 0 0" xyz="0 0 0"/>
      <geometry>
        <cylinder length="0.03" radius="0.05"/>
      </geometry>
      <material name="gray"/>
    </visual>
  </link>
  <joint name="right_wheel_joint" type="continuous">
    <origin rpy="0 0 0" xyz="0 0.19 -0.07"/>
    <parent link="base_link"/>
    <child link="right_wheel_link"/>
    <axis xyz="0 1 0"/>
  </joint>
  <link name="right_wheel_link">
    <visual>
      <origin rpy="1.5707963 0 0" xyz="0 0 0"/>
      <geometry>
        <cylinder length="0.03" radius="0.05"/>
      </geometry>
      <material name="gray"/>
    </visual>
  </link>
  <joint name="front_caster_box_base_joint" type="fixed">
    <origin rpy="0 0 0" xyz="-0.18 0 -0.085"/>
    <parent link="base_link"/>
    <child link="front_caster_box"/>
  </joint>
  <link name="front_caster_box">
    <visual>
      <origin rpy="0 0 0" xyz="0 0 0"/>
      <geometry>
        <box rpy="0 0 0" size="0.01 0.01 0.01"/>
      </geometry>
      <material name="black"/>
    </visual>
  </link>
  <joint name="front_caster_joint" type="continuous">
    <origin rpy="0 0 0" xyz="0 0 -0.0125"/>
    <parent link="front_caster_box"/>
    <child link="front_caster_link"/>
    <axis xyz="0 1 0"/>
  </joint>
  <link name="front_caster_link">
    <visual>
      <origin rpy="0 0 0" xyz="0 0 0"/>
      <geometry>
        <sphere radius="0.015"/>
      </geometry>
      <material name="black"/>
    </visual>
  </link>
  <joint name="back_caster_box_base_joint" type="fixed">
    <origin rpy="0 0 0" xyz="0.18 0 -0.085"/>
    <parent link="base_link"/>
    <child link="back_caster_box"/>
  </joint>
  <link name="back_caster_box">
    <visual>
      <origin rpy="0 0 0" xyz="0 0 0"/>
      <geometry>
        <box rpy="0 0 0" size="0.01 0.01 0.01"/>
      </geometry>
      <material name="black"/>
    </visual>
  </link>
  <joint name="back_caster_joint" type="continuous">
    <origin rpy="0 0 0" xyz="0 0 -0.0125"/>
    <parent link="back_caster_box"/>
    <child link="back_caster_link"/>
    <axis xyz="0 1 0"/>
  </joint>
  <link name="back_caster_link">
    <visual>
      <origin rpy="0 0 0" xyz="0 0 0"/>
      <geometry>
        <sphere radius="0.015"/>
      </geometry>
      <material name="black"/>
    </visual>
  </link>
</robot>

