<?xml version="1.0" ?>
<!-- =================================================================================== -->
<!-- |    This document was autogenerated by xacro from use_robot_gazebo.xacro         | -->
<!-- |    EDITING THIS FILE BY HAND IS NOT RECOMMENDED                                 | -->
<!-- =================================================================================== -->
<robot name="my_robot" xmlns:xacro="http://www.ros.org/wiki/xacro">
  <!-- Macro for color -->
  <material name="yellow">
    <color rgba="1 0.4 0 1"/>
  </material>
  <material name="black">
    <color rgba="0 0 0 0.95"/>
  </material>
  <material name="blue">
    <color rgba="0 0 1 1"/>
  </material>
  <material name="gray">
    <color rgba="0.75 0.75 0.75 0.95"/>
  </material>
  <link name="base_footprint">
    <visual>
      <origin rpy="0 0 0" xyz="0 0 0"/>
      <geometry>
        <box size="0.001 0.001 0.001"/>
      </geometry>
    </visual>
  </link>
  <gazebo reference="base_footprint">
    <turnGravityOff>false</turnGravityOff>
  </gazebo>
  <joint name="base_footprint" type="fixed">
    <origin rpy="0 0 0" xyz="0 0 0.12"/>
    <parent link="base_footprint"/>
    <child link="base_link"/>
  </joint>
  <link name="base_link">
    <visual>
      <origin rpy="0 0 0" xyz="0 0 0"/>
      <geometry>
        <cylinder length="0.16" radius="0.2"/>
      </geometry>
      <material name="blue"/>
    </visual>
    <collision>
      <origin rpy="0 0 0" xyz="0 0 0"/>
      <geometry>
        <cylinder length="0.16" radius="0.2"/>
      </geometry>
    </collision>
    <inertial>
      <mass value="20"/>
      <inertia ixx="0.242666666667" ixy="0" ixz="0" iyy="0.242666666667" iyz="0" izz="0.4"/>
    </inertial>
  </link>
  <gazebo reference="base_link">
    <material>Gazebo/Blue</material>
  </gazebo>
  <joint name="left_wheel_joint" type="continuous">
    <origin rpy="0 0 0" xyz="0 -0.19 -0.07"/>
    <parent link="base_link"/>
    <child link="left_wheel_link"/>
    <axis xyz="0 1 0"/>
  </joint>
  <link name="left_wheel_link">
    <visual>
      <origin rpy="1.5707963 0 0" xyz="0 0 0"/>
      <geometry>
        <cylinder length="0.03" radius="0.05"/>
      </geometry>
      <material name="gray"/>
    </visual>
    <collision>
      <origin rpy="1.5707963 0 0" xyz="0 0 0"/>
      <geometry>
        <cylinder length="0.03" radius="0.05"/>
      </geometry>
    </collision>
    <inertial>
      <mass value="2"/>
      <inertia ixx="0.0014" ixy="0" ixz="0" iyy="0.0014" iyz="0" izz="0.0025"/>
    </inertial>
  </link>
  <gazebo reference="left_wheel_link">
    <material>Gazebo/Gray</material>
  </gazebo>
  <!-- Transmission: transmission is very important to link joint and controller -->
  <transmission name="left_wheel_joint_trans">
    <type>transmission_interface/SimpleTransmission</type>
    <joint name="left_wheel_joint">
      <hardwareInterface>hardware_interface/VelocityJointInterface</hardwareInterface>
    </joint>
    <actuator name="left_wheel_joint_motor">
      <hardwareInterface>hardware_interface/VelocityJointInterface</hardwareInterface>
      <mechanicalReduction>1</mechanicalReduction>
    </actuator>
  </transmission>
  <joint name="right_wheel_joint" type="continuous">
    <origin rpy="0 0 0" xyz="0 0.19 -0.07"/>
    <parent link="base_link"/>
    <child link="right_wheel_link"/>
    <axis xyz="0 1 0"/>
  </joint>
  <link name="right_wheel_link">
    <visual>
      <origin rpy="1.5707963 0 0" xyz="0 0 0"/>
      <geometry>
        <cylinder length="0.03" radius="0.05"/>
      </geometry>
      <material name="gray"/>
    </visual>
    <collision>
      <origin rpy="1.5707963 0 0" xyz="0 0 0"/>
      <geometry>
        <cylinder length="0.03" radius="0.05"/>
      </geometry>
    </collision>
    <inertial>
      <mass value="2"/>
      <inertia ixx="0.0014" ixy="0" ixz="0" iyy="0.0014" iyz="0" izz="0.0025"/>
    </inertial>
  </link>
  <gazebo reference="right_wheel_link">
    <material>Gazebo/Gray</material>
  </gazebo>
  <!-- Transmission: transmission is very important to link joint and controller -->
  <transmission name="right_wheel_joint_trans">
    <type>transmission_interface/SimpleTransmission</type>
    <joint name="right_wheel_joint">
      <hardwareInterface>hardware_interface/VelocityJointInterface</hardwareInterface>
    </joint>
    <actuator name="right_wheel_joint_motor">
      <hardwareInterface>hardware_interface/VelocityJointInterface</hardwareInterface>
      <mechanicalReduction>1</mechanicalReduction>
    </actuator>
  </transmission>
  <joint name="front_caster_joint" type="continuous">
    <origin rpy="0 0 0" xyz="-0.18 0 -0.09"/>
    <parent link="base_link"/>
    <child link="front_caster_link"/>
    <axis xyz="0 1 0"/>
  </joint>
  <link name="front_caster_link">
    <visual>
      <origin rpy="0 0 0" xyz="0 0 0"/>
      <geometry>
        <sphere radius="0.02"/>
      </geometry>
      <material name="black"/>
    </visual>
    <collision>
      <origin rpy="0 0 0" xyz="0 0 0"/>
      <geometry>
        <sphere radius="0.02"/>
      </geometry>
    </collision>
    <inertial>
      <mass value="0.5"/>
      <inertia ixx="8e-05" ixy="0" ixz="0" iyy="8e-05" iyz="0" izz="8e-05"/>
    </inertial>
  </link>
  <gazebo reference="front_caster_link">
    <material>Gazebo/Black</material>
  </gazebo>
  <joint name="back_caster_joint" type="continuous">
    <origin rpy="0 0 0" xyz="0.18 0 -0.09"/>
    <parent link="base_link"/>
    <child link="back_caster_link"/>
    <axis xyz="0 1 0"/>
  </joint>
  <link name="back_caster_link">
    <visual>
      <origin rpy="0 0 0" xyz="0 0 0"/>
      <geometry>
        <sphere radius="0.02"/>
      </geometry>
      <material name="black"/>
    </visual>
    <collision>
      <origin rpy="0 0 0" xyz="0 0 0"/>
      <geometry>
        <sphere radius="0.02"/>
      </geometry>
    </collision>
    <inertial>
      <mass value="0.5"/>
      <inertia ixx="8e-05" ixy="0" ixz="0" iyy="8e-05" iyz="0" izz="8e-05"/>
    </inertial>
  </link>
  <gazebo reference="back_caster_link">
    <material>Gazebo/Black</material>
  </gazebo>
  <gazebo>
    <plugin filename="libgazebo_ros_diff_drive.so" name="differential_drive_controller">
      <rosDebugLevel>Debug</rosDebugLevel>
      <publishWheelTF>true</publishWheelTF>
      <robotNamespace>/</robotNamespace>
      <publishTf>1</publishTf>
      <publishWheelJointState>true</publishWheelJointState>
      <alwaysOn>true</alwaysOn>
      <updateRate>100.0</updateRate>
      <legacyMode>true</legacyMode>
      <leftJoint>left_wheel_joint</leftJoint>
      <rightJoint>right_wheel_joint</rightJoint>
      <wheelSeparation>0.38</wheelSeparation>
      <wheelDiameter>0.1</wheelDiameter>
      <broadcasterTF>1</broadcasterTF>
      <wheelTorque>30</wheelTorque>
      <wheelAcceleration>1.8</wheelAcceleration>
      <commandTopic>cmd_vel</commandTopic>
      <odometryFrame>odom</odometryFrame>
      <odometryTopic>odom</odometryTopic>
      <robotBaseFrame>base_footprint</robotBaseFrame>
    </plugin>
  </gazebo>
</robot>

